[2023-01-26 14:03:43,450] {taskinstance.py:1159} INFO - Dependencies all met for <TaskInstance: d1_script.generate_dim manual__2023-01-26T14:03:39.809140+00:00 [queued]>
[2023-01-26 14:03:43,463] {taskinstance.py:1159} INFO - Dependencies all met for <TaskInstance: d1_script.generate_dim manual__2023-01-26T14:03:39.809140+00:00 [queued]>
[2023-01-26 14:03:43,464] {taskinstance.py:1356} INFO - 
--------------------------------------------------------------------------------
[2023-01-26 14:03:43,464] {taskinstance.py:1357} INFO - Starting attempt 1 of 1
[2023-01-26 14:03:43,464] {taskinstance.py:1358} INFO - 
--------------------------------------------------------------------------------
[2023-01-26 14:03:43,481] {taskinstance.py:1377} INFO - Executing <Task(PythonOperator): generate_dim> on 2023-01-26 14:03:39.809140+00:00
[2023-01-26 14:03:43,487] {standard_task_runner.py:52} INFO - Started process 359 to run task
[2023-01-26 14:03:43,491] {standard_task_runner.py:79} INFO - Running: ['***', 'tasks', 'run', 'd1_script', 'generate_dim', 'manual__2023-01-26T14:03:39.809140+00:00', '--job-id', '5', '--raw', '--subdir', 'DAGS_FOLDER/d1_script.py', '--cfg-path', '/tmp/tmp0ajbce2f', '--error-file', '/tmp/tmpux_lzw_p']
[2023-01-26 14:03:43,492] {standard_task_runner.py:80} INFO - Job 5: Subtask generate_dim
[2023-01-26 14:03:43,547] {task_command.py:369} INFO - Running <TaskInstance: d1_script.generate_dim manual__2023-01-26T14:03:39.809140+00:00 [running]> on host ec233ae30e03
[2023-01-26 14:03:43,628] {taskinstance.py:1571} INFO - Exporting the following env vars:
AIRFLOW_CTX_DAG_OWNER=***
AIRFLOW_CTX_DAG_ID=d1_script
AIRFLOW_CTX_TASK_ID=generate_dim
AIRFLOW_CTX_EXECUTION_DATE=2023-01-26T14:03:39.809140+00:00
AIRFLOW_CTX_TRY_NUMBER=1
AIRFLOW_CTX_DAG_RUN_ID=manual__2023-01-26T14:03:39.809140+00:00
[2023-01-26 14:03:43,747] {logging_mixin.py:115} INFO - [INFO] GET DATA FROM MYSQL IS SUCCESSFUL
[2023-01-26 14:03:43,748] {logging_mixin.py:115} INFO - [INFO] TOTAL GETTING DATA TIME FROM MYSQL IS 0.07501363754272461 S
[2023-01-26 14:03:43,832] {taskinstance.py:1889} ERROR - Task failed with exception
Traceback (most recent call last):
  File "/home/airflow/.local/lib/python3.7/site-packages/sqlalchemy/engine/base.py", line 1706, in _execute_context
    cursor, statement, parameters, context
  File "/home/airflow/.local/lib/python3.7/site-packages/sqlalchemy/engine/default.py", line 716, in do_execute
    cursor.execute(statement, parameters)
psycopg2.errors.UniqueViolation: duplicate key value violates unique constraint "pg_type_typname_nsp_index"
DETAIL:  Key (typname, typnamespace)=(dim_case, 2200) already exists.


The above exception was the direct cause of the following exception:

Traceback (most recent call last):
  File "/home/airflow/.local/lib/python3.7/site-packages/airflow/operators/python.py", line 171, in execute
    return_value = self.execute_callable()
  File "/home/airflow/.local/lib/python3.7/site-packages/airflow/operators/python.py", line 189, in execute_callable
    return self.python_callable(*self.op_args, **self.op_kwargs)
  File "/opt/airflow/dags/d1_script.py", line 73, in func_generate_dim
    transformer.create_dimension_case()
  File "/opt/airflow/dags/modules/transformer.py", line 85, in create_dimension_case
    df.to_sql(con=self.engine_postgres, name='dim_case', index=False, if_exists='replace')
  File "/home/airflow/.local/lib/python3.7/site-packages/pandas/core/generic.py", line 2882, in to_sql
    method=method,
  File "/home/airflow/.local/lib/python3.7/site-packages/pandas/io/sql.py", line 728, in to_sql
    **engine_kwargs,
  File "/home/airflow/.local/lib/python3.7/site-packages/pandas/io/sql.py", line 1758, in to_sql
    dtype=dtype,
  File "/home/airflow/.local/lib/python3.7/site-packages/pandas/io/sql.py", line 1650, in prep_table
    table.create()
  File "/home/airflow/.local/lib/python3.7/site-packages/pandas/io/sql.py", line 867, in create
    self._execute_create()
  File "/home/airflow/.local/lib/python3.7/site-packages/pandas/io/sql.py", line 853, in _execute_create
    self.table.create()
  File "/home/airflow/.local/lib/python3.7/site-packages/sqlalchemy/sql/schema.py", line 943, in create
    bind._run_ddl_visitor(ddl.SchemaGenerator, self, checkfirst=checkfirst)
  File "/home/airflow/.local/lib/python3.7/site-packages/sqlalchemy/engine/base.py", line 3008, in _run_ddl_visitor
    conn._run_ddl_visitor(visitorcallable, element, **kwargs)
  File "/home/airflow/.local/lib/python3.7/site-packages/sqlalchemy/engine/base.py", line 2016, in _run_ddl_visitor
    visitorcallable(self.dialect, self, **kwargs).traverse_single(element)
  File "/home/airflow/.local/lib/python3.7/site-packages/sqlalchemy/sql/visitors.py", line 483, in traverse_single
    return meth(obj, **kw)
  File "/home/airflow/.local/lib/python3.7/site-packages/sqlalchemy/sql/ddl.py", line 895, in visit_table
    include_foreign_key_constraints,  # noqa
  File "/home/airflow/.local/lib/python3.7/site-packages/sqlalchemy/engine/base.py", line 1200, in execute
    return meth(self, multiparams, params, _EMPTY_EXECUTION_OPTS)
  File "/home/airflow/.local/lib/python3.7/site-packages/sqlalchemy/sql/ddl.py", line 78, in _execute_on_connection
    self, multiparams, params, execution_options
  File "/home/airflow/.local/lib/python3.7/site-packages/sqlalchemy/engine/base.py", line 1296, in _execute_ddl
    compiled,
  File "/home/airflow/.local/lib/python3.7/site-packages/sqlalchemy/engine/base.py", line 1749, in _execute_context
    e, statement, parameters, cursor, context
  File "/home/airflow/.local/lib/python3.7/site-packages/sqlalchemy/engine/base.py", line 1930, in _handle_dbapi_exception
    sqlalchemy_exception, with_traceback=exc_info[2], from_=e
  File "/home/airflow/.local/lib/python3.7/site-packages/sqlalchemy/util/compat.py", line 211, in raise_
    raise exception
  File "/home/airflow/.local/lib/python3.7/site-packages/sqlalchemy/engine/base.py", line 1706, in _execute_context
    cursor, statement, parameters, context
  File "/home/airflow/.local/lib/python3.7/site-packages/sqlalchemy/engine/default.py", line 716, in do_execute
    cursor.execute(statement, parameters)
sqlalchemy.exc.IntegrityError: (psycopg2.errors.UniqueViolation) duplicate key value violates unique constraint "pg_type_typname_nsp_index"
DETAIL:  Key (typname, typnamespace)=(dim_case, 2200) already exists.

[SQL: 
CREATE TABLE dim_case (
	id BIGINT, 
	status_name TEXT, 
	status_detail TEXT, 
	status TEXT
)

]
(Background on this error at: http://sqlalche.me/e/14/gkpj)
[2023-01-26 14:03:43,856] {taskinstance.py:1400} INFO - Marking task as FAILED. dag_id=d1_script, task_id=generate_dim, execution_date=20230126T140339, start_date=20230126T140343, end_date=20230126T140343
[2023-01-26 14:03:43,871] {standard_task_runner.py:97} ERROR - Failed to execute job 5 for task generate_dim ((psycopg2.errors.UniqueViolation) duplicate key value violates unique constraint "pg_type_typname_nsp_index"
DETAIL:  Key (typname, typnamespace)=(dim_case, 2200) already exists.

[SQL: 
CREATE TABLE dim_case (
	id BIGINT, 
	status_name TEXT, 
	status_detail TEXT, 
	status TEXT
)

]
(Background on this error at: http://sqlalche.me/e/14/gkpj); 359)
[2023-01-26 14:03:43,904] {local_task_job.py:156} INFO - Task exited with return code 1
[2023-01-26 14:03:43,949] {local_task_job.py:273} INFO - 0 downstream tasks scheduled from follow-on schedule check
